<sdf version='1.11'>
  <model name='robot'>
    <link name='base_link'>
      <inertial>
        <pose>0 0 0.40000000000000002 0 0 0</pose>
        <mass>140</mass>
        <inertia>
          <ixx>2.916666666666679</ixx>
          <ixy>0</ixy>
          <ixz>0</ixz>
          <iyy>4.5791666666666764</iyy>
          <iyz>0</iyz>
          <izz>5.3958333333333339</izz>
        </inertia>
      </inertial>
      <collision name='base_link_fixed_joint_lump__body_link_collision'>
        <pose>0 0 0.40000000000000002 0 0 0</pose>
        <geometry>
          <box>
            <size>0.55000000000000004 0.40000000000000002 0.29999999999999999</size>
          </box>
        </geometry>
        <surface>
          <contact>
            <ode/>
          </contact>
          <friction>
            <ode/>
          </friction>
        </surface>
      </collision>
      <visual name='base_link_fixed_joint_lump__body_link_visual'>
        <pose>0 0 0.40000000000000002 0 0 0</pose>
        <geometry>
          <box>
            <size>0.55000000000000004 0.40000000000000002 0.29999999999999999</size>
          </box>
        </geometry>
        <material>
          <script>
            <name>Gazebo/Blue</name>
            <uri>file://media/materials/scripts/gazebo.material</uri>
          </script>
          <diffuse>0.25 0.25 1 1</diffuse>
          <ambient>0.25 0.25 1 1</ambient>
        </material>
      </visual>
    </link>
    <joint name='coxa_joint_0' type='revolute'>
      <pose relative_to='base_link'>0.27500000000000002 -0.20000000000000001 0.25 0 0 0</pose>
      <parent>base_link</parent>
      <child>coxa_link_0</child>
      <axis>
        <xyz>0 0 1</xyz>
        <limit>
          <lower>-3.1400000000000001</lower>
          <upper>3.1400000000000001</upper>
          <effort>250</effort>
          <velocity>10</velocity>
        </limit>
        <dynamics>
          <spring_reference>0</spring_reference>
          <spring_stiffness>0</spring_stiffness>
        </dynamics>
      </axis>
    </joint>
    <link name='coxa_link_0'>
      <pose relative_to='coxa_joint_0'>0 0 0 0 0 0</pose>
      <inertial>
        <pose>0.029999999999999999 -0.050000000000000003 -0.050000000000000003 0 1.5700000000004057 0</pose>
        <mass>0.30099999999999999</mass>
        <inertia>
          <ixx>0.00043895833333333341</ixx>
          <ixy>0</ixy>
          <ixz>0</ixz>
          <iyy>0.00043895833333333341</iyy>
          <iyz>0</iyz>
          <izz>0.00037625000000000012</izz>
        </inertia>
      </inertial>
      <collision name='coxa_link_0_collision'>
        <pose>0.029999999999999999 -0.050000000000000003 -0.050000000000000003 0 1.5707963267948966 0</pose>
        <geometry>
          <cylinder>
            <length>0.10000000000000001</length>
            <radius>0.050000000000000003</radius>
          </cylinder>
        </geometry>
        <surface>
          <contact>
            <ode/>
          </contact>
          <friction>
            <ode/>
          </friction>
        </surface>
      </collision>
      <visual name='coxa_link_0_visual'>
        <pose>0.029999999999999999 -0.050000000000000003 -0.050000000000000003 0 1.5707963267948966 0</pose>
        <geometry>
          <cylinder>
            <length>0.10000000000000001</length>
            <radius>0.050000000000000003</radius>
          </cylinder>
        </geometry>
        <material>
          <script>
            <name>Gazebo/Blue</name>
            <uri>file://media/materials/scripts/gazebo.material</uri>
          </script>
          <diffuse>1 0 0 1</diffuse>
          <ambient>1 0 0 1</ambient>
        </material>
      </visual>
    </link>
    <joint name='femur_joint_0' type='revolute'>
      <pose relative_to='coxa_link_0'>0.070000000000000007 -0.050000000000000003 -0.050000000000000003 0 -1.5700000000004057 0</pose>
      <parent>coxa_link_0</parent>
      <child>femur_link_0</child>
      <axis>
        <xyz>0 0 1</xyz>
        <limit>
          <lower>-3.1400000000000001</lower>
          <upper>3.1400000000000001</upper>
          <effort>250</effort>
          <velocity>10</velocity>
        </limit>
        <dynamics>
          <spring_reference>0</spring_reference>
          <spring_stiffness>0</spring_stiffness>
        </dynamics>
      </axis>
    </joint>
    <link name='femur_link_0'>
      <pose relative_to='femur_joint_0'>0 0 0 0 0 0</pose>
      <inertial>
        <pose>0 -0.14999999999999999 -0.029999999999999999 0 0 0</pose>
        <mass>0.501</mass>
        <inertia>
          <ixx>0.003761674999999999</ixx>
          <ixy>0</ixy>
          <ixz>0</ixz>
          <iyy>4.1749999999999998e-05</iyy>
          <iyz>0</iyz>
          <izz>0.0037950749999999989</izz>
        </inertia>
      </inertial>
      <collision name='femur_link_0_collision'>
        <pose>0 -0.14999999999999999 -0.029999999999999999 0 0 0</pose>
        <geometry>
          <box>
            <size>0.029999999999999999 0.29999999999999999 0.01</size>
          </box>
        </geometry>
        <surface>
          <contact>
            <ode/>
          </contact>
          <friction>
            <ode/>
          </friction>
        </surface>
      </collision>
      <visual name='femur_link_0_visual'>
        <pose>0 -0.14999999999999999 -0.029999999999999999 0 0 0</pose>
        <geometry>
          <box>
            <size>0.029999999999999999 0.29999999999999999 0.01</size>
          </box>
        </geometry>
        <material>
          <script>
            <name>Gazebo/Orange</name>
            <uri>file://media/materials/scripts/gazebo.material</uri>
          </script>
          <diffuse>1 0.37500003 0.125 1</diffuse>
          <ambient>1 0.37500003 0.125 1</ambient>
        </material>
      </visual>
    </link>
    <joint name='tibia_joint_0' type='revolute'>
      <pose relative_to='femur_link_0'>0 -0.29999999999999999 -0.01 3.1415926535897931 0.001592653589793114 3.1415926535897931</pose>
      <parent>femur_link_0</parent>
      <child>tibia_link_0</child>
      <axis>
        <xyz>0 0 1</xyz>
        <limit>
          <lower>-3.1400000000000001</lower>
          <upper>3.1400000000000001</upper>
          <effort>250</effort>
          <velocity>10</velocity>
        </limit>
        <dynamics>
          <spring_reference>0</spring_reference>
          <spring_stiffness>0</spring_stiffness>
        </dynamics>
      </axis>
    </joint>
    <link name='tibia_link_0'>
      <pose relative_to='tibia_joint_0'>0 0 0 0 0 0</pose>
      <inertial>
        <pose>0 -0.15036069651741291 0 0 0 0</pose>
        <mass>0.40200000000000002</mass>
        <inertia>
          <ixx>0.0024606393656716459</ixx>
          <ixy>0</ixy>
          <ixz>0</ixz>
          <iyy>3.3666666666666667e-05</iyy>
          <iyz>0</iyz>
          <izz>0.0024873726990049792</izz>
        </inertia>
      </inertial>
      <collision name='tibia_link_0_collision'>
        <pose>0 -0.14999999999999999 0 0 0 0</pose>
        <geometry>
          <box>
            <size>0.029999999999999999 0.27000000000000002 0.01</size>
          </box>
        </geometry>
        <surface>
          <contact>
            <ode/>
          </contact>
          <friction>
            <ode/>
          </friction>
        </surface>
      </collision>
      <collision name='tibia_link_0_fixed_joint_lump__foot_link_0_collision_1'>
        <pose>0 -0.29499999999999998 0 0 0 0</pose>
        <geometry>
          <sphere>
            <radius>0.025000000000000001</radius>
          </sphere>
        </geometry>
        <surface>
          <contact>
            <ode/>
          </contact>
          <friction>
            <ode/>
          </friction>
        </surface>
      </collision>
      <visual name='tibia_link_0_visual'>
        <pose>0 -0.14999999999999999 0 0 0 0</pose>
        <geometry>
          <box>
            <size>0.029999999999999999 0.27000000000000002 0.01</size>
          </box>
        </geometry>
        <material>
          <script>
            <name>Gazebo/Black</name>
            <uri>file://media/materials/scripts/gazebo.material</uri>
          </script>
          <diffuse>0 0 0 1</diffuse>
          <ambient>0 0 0 1</ambient>
        </material>
      </visual>
      <visual name='tibia_link_0_fixed_joint_lump__foot_link_0_visual_1'>
        <pose>0 -0.29499999999999998 0 0 0 0</pose>
        <geometry>
          <sphere>
            <radius>0.025000000000000001</radius>
          </sphere>
        </geometry>
        <material>
          <script>
            <name>Gazebo/White</name>
            <uri>file://media/materials/scripts/gazebo.material</uri>
          </script>
          <diffuse>1 1 1 1</diffuse>
          <ambient>1 1 1 1</ambient>
        </material>
      </visual>
    </link>
    <joint name='coxa_joint_1' type='revolute'>
      <pose relative_to='base_link'>0 -0.20000000000000001 0.25 0 0 0</pose>
      <parent>base_link</parent>
      <child>coxa_link_1</child>
      <axis>
        <xyz>0 0 1</xyz>
        <limit>
          <lower>-3.1400000000000001</lower>
          <upper>3.1400000000000001</upper>
          <effort>250</effort>
          <velocity>10</velocity>
        </limit>
        <dynamics>
          <spring_reference>0</spring_reference>
          <spring_stiffness>0</spring_stiffness>
        </dynamics>
      </axis>
    </joint>
    <link name='coxa_link_1'>
      <pose relative_to='coxa_joint_1'>0 0 0 0 0 0</pose>
      <inertial>
        <pose>0.029999999999999999 -0.050000000000000003 -0.050000000000000003 0 1.5700000000004057 0</pose>
        <mass>0.30099999999999999</mass>
        <inertia>
          <ixx>0.00043895833333333341</ixx>
          <ixy>0</ixy>
          <ixz>0</ixz>
          <iyy>0.00043895833333333341</iyy>
          <iyz>0</iyz>
          <izz>0.00037625000000000012</izz>
        </inertia>
      </inertial>
      <collision name='coxa_link_1_collision'>
        <pose>0.029999999999999999 -0.050000000000000003 -0.050000000000000003 0 1.5707963267948966 0</pose>
        <geometry>
          <cylinder>
            <length>0.10000000000000001</length>
            <radius>0.050000000000000003</radius>
          </cylinder>
        </geometry>
        <surface>
          <contact>
            <ode/>
          </contact>
          <friction>
            <ode/>
          </friction>
        </surface>
      </collision>
      <visual name='coxa_link_1_visual'>
        <pose>0.029999999999999999 -0.050000000000000003 -0.050000000000000003 0 1.5707963267948966 0</pose>
        <geometry>
          <cylinder>
            <length>0.10000000000000001</length>
            <radius>0.050000000000000003</radius>
          </cylinder>
        </geometry>
        <material>
          <script>
            <name>Gazebo/Blue</name>
            <uri>file://media/materials/scripts/gazebo.material</uri>
          </script>
          <diffuse>1 0 0 1</diffuse>
          <ambient>1 0 0 1</ambient>
        </material>
      </visual>
    </link>
    <joint name='femur_joint_1' type='revolute'>
      <pose relative_to='coxa_link_1'>0.070000000000000007 -0.050000000000000003 -0.050000000000000003 0 -1.5700000000004057 0</pose>
      <parent>coxa_link_1</parent>
      <child>femur_link_1</child>
      <axis>
        <xyz>0 0 1</xyz>
        <limit>
          <lower>-3.1400000000000001</lower>
          <upper>3.1400000000000001</upper>
          <effort>250</effort>
          <velocity>10</velocity>
        </limit>
        <dynamics>
          <spring_reference>0</spring_reference>
          <spring_stiffness>0</spring_stiffness>
        </dynamics>
      </axis>
    </joint>
    <link name='femur_link_1'>
      <pose relative_to='femur_joint_1'>0 0 0 0 0 0</pose>
      <inertial>
        <pose>0 -0.14999999999999999 -0.029999999999999999 0 0 0</pose>
        <mass>0.501</mass>
        <inertia>
          <ixx>0.003761674999999999</ixx>
          <ixy>0</ixy>
          <ixz>0</ixz>
          <iyy>4.1749999999999998e-05</iyy>
          <iyz>0</iyz>
          <izz>0.0037950749999999989</izz>
        </inertia>
      </inertial>
      <collision name='femur_link_1_collision'>
        <pose>0 -0.14999999999999999 -0.029999999999999999 0 0 0</pose>
        <geometry>
          <box>
            <size>0.029999999999999999 0.29999999999999999 0.01</size>
          </box>
        </geometry>
        <surface>
          <contact>
            <ode/>
          </contact>
          <friction>
            <ode/>
          </friction>
        </surface>
      </collision>
      <visual name='femur_link_1_visual'>
        <pose>0 -0.14999999999999999 -0.029999999999999999 0 0 0</pose>
        <geometry>
          <box>
            <size>0.029999999999999999 0.29999999999999999 0.01</size>
          </box>
        </geometry>
        <material>
          <script>
            <name>Gazebo/Orange</name>
            <uri>file://media/materials/scripts/gazebo.material</uri>
          </script>
          <diffuse>1 0.37500003 0.125 1</diffuse>
          <ambient>1 0.37500003 0.125 1</ambient>
        </material>
      </visual>
    </link>
    <joint name='tibia_joint_1' type='revolute'>
      <pose relative_to='femur_link_1'>0 -0.29999999999999999 -0.01 3.1415926535897931 0.001592653589793114 3.1415926535897931</pose>
      <parent>femur_link_1</parent>
      <child>tibia_link_1</child>
      <axis>
        <xyz>0 0 1</xyz>
        <limit>
          <lower>-3.1400000000000001</lower>
          <upper>3.1400000000000001</upper>
          <effort>250</effort>
          <velocity>10</velocity>
        </limit>
        <dynamics>
          <spring_reference>0</spring_reference>
          <spring_stiffness>0</spring_stiffness>
        </dynamics>
      </axis>
    </joint>
    <link name='tibia_link_1'>
      <pose relative_to='tibia_joint_1'>0 0 0 0 0 0</pose>
      <inertial>
        <pose>0 -0.15036069651741291 0 0 0 0</pose>
        <mass>0.40200000000000002</mass>
        <inertia>
          <ixx>0.0024606393656716459</ixx>
          <ixy>0</ixy>
          <ixz>0</ixz>
          <iyy>3.3666666666666667e-05</iyy>
          <iyz>0</iyz>
          <izz>0.0024873726990049792</izz>
        </inertia>
      </inertial>
      <collision name='tibia_link_1_collision'>
        <pose>0 -0.14999999999999999 0 0 0 0</pose>
        <geometry>
          <box>
            <size>0.029999999999999999 0.27000000000000002 0.01</size>
          </box>
        </geometry>
        <surface>
          <contact>
            <ode/>
          </contact>
          <friction>
            <ode/>
          </friction>
        </surface>
      </collision>
      <collision name='tibia_link_1_fixed_joint_lump__foot_link_1_collision_1'>
        <pose>0 -0.29499999999999998 0 0 0 0</pose>
        <geometry>
          <sphere>
            <radius>0.025000000000000001</radius>
          </sphere>
        </geometry>
        <surface>
          <contact>
            <ode/>
          </contact>
          <friction>
            <ode/>
          </friction>
        </surface>
      </collision>
      <visual name='tibia_link_1_visual'>
        <pose>0 -0.14999999999999999 0 0 0 0</pose>
        <geometry>
          <box>
            <size>0.029999999999999999 0.27000000000000002 0.01</size>
          </box>
        </geometry>
        <material>
          <script>
            <name>Gazebo/Black</name>
            <uri>file://media/materials/scripts/gazebo.material</uri>
          </script>
          <diffuse>0 0 0 1</diffuse>
          <ambient>0 0 0 1</ambient>
        </material>
      </visual>
      <visual name='tibia_link_1_fixed_joint_lump__foot_link_1_visual_1'>
        <pose>0 -0.29499999999999998 0 0 0 0</pose>
        <geometry>
          <sphere>
            <radius>0.025000000000000001</radius>
          </sphere>
        </geometry>
        <material>
          <script>
            <name>Gazebo/White</name>
            <uri>file://media/materials/scripts/gazebo.material</uri>
          </script>
          <diffuse>1 1 1 1</diffuse>
          <ambient>1 1 1 1</ambient>
        </material>
      </visual>
    </link>
    <joint name='coxa_joint_2' type='revolute'>
      <pose relative_to='base_link'>-0.27500000000000002 -0.20000000000000001 0.25 0 0 0</pose>
      <parent>base_link</parent>
      <child>coxa_link_2</child>
      <axis>
        <xyz>0 0 1</xyz>
        <limit>
          <lower>-3.1400000000000001</lower>
          <upper>3.1400000000000001</upper>
          <effort>250</effort>
          <velocity>10</velocity>
        </limit>
        <dynamics>
          <spring_reference>0</spring_reference>
          <spring_stiffness>0</spring_stiffness>
        </dynamics>
      </axis>
    </joint>
    <link name='coxa_link_2'>
      <pose relative_to='coxa_joint_2'>0 0 0 0 0 0</pose>
      <inertial>
        <pose>-0.029999999999999999 -0.050000000000000003 -0.050000000000000003 0 1.5700000000004057 0</pose>
        <mass>0.30099999999999999</mass>
        <inertia>
          <ixx>0.00043895833333333341</ixx>
          <ixy>0</ixy>
          <ixz>0</ixz>
          <iyy>0.00043895833333333341</iyy>
          <iyz>0</iyz>
          <izz>0.00037625000000000012</izz>
        </inertia>
      </inertial>
      <collision name='coxa_link_2_collision'>
        <pose>-0.029999999999999999 -0.050000000000000003 -0.050000000000000003 0 1.5707963267948966 0</pose>
        <geometry>
          <cylinder>
            <length>0.10000000000000001</length>
            <radius>0.050000000000000003</radius>
          </cylinder>
        </geometry>
        <surface>
          <contact>
            <ode/>
          </contact>
          <friction>
            <ode/>
          </friction>
        </surface>
      </collision>
      <visual name='coxa_link_2_visual'>
        <pose>-0.029999999999999999 -0.050000000000000003 -0.050000000000000003 0 1.5707963267948966 0</pose>
        <geometry>
          <cylinder>
            <length>0.10000000000000001</length>
            <radius>0.050000000000000003</radius>
          </cylinder>
        </geometry>
        <material>
          <script>
            <name>Gazebo/Blue</name>
            <uri>file://media/materials/scripts/gazebo.material</uri>
          </script>
          <diffuse>1 0 0 1</diffuse>
          <ambient>1 0 0 1</ambient>
        </material>
      </visual>
    </link>
    <joint name='femur_joint_2' type='revolute'>
      <pose relative_to='coxa_link_2'>-0.070000000000000007 -0.050000000000000003 -0.050000000000000003 0 -1.5700000000004057 0</pose>
      <parent>coxa_link_2</parent>
      <child>femur_link_2</child>
      <axis>
        <xyz>0 0 1</xyz>
        <limit>
          <lower>-3.1400000000000001</lower>
          <upper>3.1400000000000001</upper>
          <effort>250</effort>
          <velocity>10</velocity>
        </limit>
        <dynamics>
          <spring_reference>0</spring_reference>
          <spring_stiffness>0</spring_stiffness>
        </dynamics>
      </axis>
    </joint>
    <link name='femur_link_2'>
      <pose relative_to='femur_joint_2'>0 0 0 0 0 0</pose>
      <inertial>
        <pose>0 -0.14999999999999999 0.029999999999999999 0 0 0</pose>
        <mass>0.501</mass>
        <inertia>
          <ixx>0.003761674999999999</ixx>
          <ixy>0</ixy>
          <ixz>0</ixz>
          <iyy>4.1749999999999998e-05</iyy>
          <iyz>0</iyz>
          <izz>0.0037950749999999989</izz>
        </inertia>
      </inertial>
      <collision name='femur_link_2_collision'>
        <pose>0 -0.14999999999999999 0.029999999999999999 0 0 0</pose>
        <geometry>
          <box>
            <size>0.029999999999999999 0.29999999999999999 0.01</size>
          </box>
        </geometry>
        <surface>
          <contact>
            <ode/>
          </contact>
          <friction>
            <ode/>
          </friction>
        </surface>
      </collision>
      <visual name='femur_link_2_visual'>
        <pose>0 -0.14999999999999999 0.029999999999999999 0 0 0</pose>
        <geometry>
          <box>
            <size>0.029999999999999999 0.29999999999999999 0.01</size>
          </box>
        </geometry>
        <material>
          <script>
            <name>Gazebo/Orange</name>
            <uri>file://media/materials/scripts/gazebo.material</uri>
          </script>
          <diffuse>1 0.37500003 0.125 1</diffuse>
          <ambient>1 0.37500003 0.125 1</ambient>
        </material>
      </visual>
    </link>
    <joint name='tibia_joint_2' type='revolute'>
      <pose relative_to='femur_link_2'>0 -0.29999999999999999 0.01 3.1415926535897931 0.001592653589793114 3.1415926535897931</pose>
      <parent>femur_link_2</parent>
      <child>tibia_link_2</child>
      <axis>
        <xyz>0 0 1</xyz>
        <limit>
          <lower>-3.1400000000000001</lower>
          <upper>3.1400000000000001</upper>
          <effort>250</effort>
          <velocity>10</velocity>
        </limit>
        <dynamics>
          <spring_reference>0</spring_reference>
          <spring_stiffness>0</spring_stiffness>
        </dynamics>
      </axis>
    </joint>
    <link name='tibia_link_2'>
      <pose relative_to='tibia_joint_2'>0 0 0 0 0 0</pose>
      <inertial>
        <pose>0 -0.15036069651741291 0 0 0 0</pose>
        <mass>0.40200000000000002</mass>
        <inertia>
          <ixx>0.0024606393656716459</ixx>
          <ixy>0</ixy>
          <ixz>0</ixz>
          <iyy>3.3666666666666667e-05</iyy>
          <iyz>0</iyz>
          <izz>0.0024873726990049792</izz>
        </inertia>
      </inertial>
      <collision name='tibia_link_2_collision'>
        <pose>0 -0.14999999999999999 0 0 0 0</pose>
        <geometry>
          <box>
            <size>0.029999999999999999 0.27000000000000002 0.01</size>
          </box>
        </geometry>
        <surface>
          <contact>
            <ode/>
          </contact>
          <friction>
            <ode/>
          </friction>
        </surface>
      </collision>
      <collision name='tibia_link_2_fixed_joint_lump__foot_link_2_collision_1'>
        <pose>0 -0.29499999999999998 0 0 0 0</pose>
        <geometry>
          <sphere>
            <radius>0.025000000000000001</radius>
          </sphere>
        </geometry>
        <surface>
          <contact>
            <ode/>
          </contact>
          <friction>
            <ode/>
          </friction>
        </surface>
      </collision>
      <visual name='tibia_link_2_visual'>
        <pose>0 -0.14999999999999999 0 0 0 0</pose>
        <geometry>
          <box>
            <size>0.029999999999999999 0.27000000000000002 0.01</size>
          </box>
        </geometry>
        <material>
          <script>
            <name>Gazebo/Black</name>
            <uri>file://media/materials/scripts/gazebo.material</uri>
          </script>
          <diffuse>0 0 0 1</diffuse>
          <ambient>0 0 0 1</ambient>
        </material>
      </visual>
      <visual name='tibia_link_2_fixed_joint_lump__foot_link_2_visual_1'>
        <pose>0 -0.29499999999999998 0 0 0 0</pose>
        <geometry>
          <sphere>
            <radius>0.025000000000000001</radius>
          </sphere>
        </geometry>
        <material>
          <script>
            <name>Gazebo/White</name>
            <uri>file://media/materials/scripts/gazebo.material</uri>
          </script>
          <diffuse>1 1 1 1</diffuse>
          <ambient>1 1 1 1</ambient>
        </material>
      </visual>
    </link>
    <joint name='coxa_joint_3' type='revolute'>
      <pose relative_to='base_link'>0.27500000000000002 0.20000000000000001 0.25 0 0 3.1400000000000001</pose>
      <parent>base_link</parent>
      <child>coxa_link_3</child>
      <axis>
        <xyz>0 0 1</xyz>
        <limit>
          <lower>-3.1400000000000001</lower>
          <upper>3.1400000000000001</upper>
          <effort>250</effort>
          <velocity>10</velocity>
        </limit>
        <dynamics>
          <spring_reference>0</spring_reference>
          <spring_stiffness>0</spring_stiffness>
        </dynamics>
      </axis>
    </joint>
    <link name='coxa_link_3'>
      <pose relative_to='coxa_joint_3'>0 0 0 0 0 0</pose>
      <inertial>
        <pose>-0.029999999999999999 -0.050000000000000003 -0.050000000000000003 0 1.5700000000004057 0</pose>
        <mass>0.30099999999999999</mass>
        <inertia>
          <ixx>0.00043895833333333341</ixx>
          <ixy>0</ixy>
          <ixz>0</ixz>
          <iyy>0.00043895833333333341</iyy>
          <iyz>0</iyz>
          <izz>0.00037625000000000012</izz>
        </inertia>
      </inertial>
      <collision name='coxa_link_3_collision'>
        <pose>-0.029999999999999999 -0.050000000000000003 -0.050000000000000003 0 1.5707963267948966 0</pose>
        <geometry>
          <cylinder>
            <length>0.10000000000000001</length>
            <radius>0.050000000000000003</radius>
          </cylinder>
        </geometry>
        <surface>
          <contact>
            <ode/>
          </contact>
          <friction>
            <ode/>
          </friction>
        </surface>
      </collision>
      <visual name='coxa_link_3_visual'>
        <pose>-0.029999999999999999 -0.050000000000000003 -0.050000000000000003 0 1.5707963267948966 0</pose>
        <geometry>
          <cylinder>
            <length>0.10000000000000001</length>
            <radius>0.050000000000000003</radius>
          </cylinder>
        </geometry>
        <material>
          <script>
            <name>Gazebo/Blue</name>
            <uri>file://media/materials/scripts/gazebo.material</uri>
          </script>
          <diffuse>1 0 0 1</diffuse>
          <ambient>1 0 0 1</ambient>
        </material>
      </visual>
    </link>
    <joint name='femur_joint_3' type='revolute'>
      <pose relative_to='coxa_link_3'>-0.070000000000000007 -0.050000000000000003 -0.050000000000000003 0 -1.5700000000004057 0</pose>
      <parent>coxa_link_3</parent>
      <child>femur_link_3</child>
      <axis>
        <xyz>0 0 1</xyz>
        <limit>
          <lower>-3.1400000000000001</lower>
          <upper>3.1400000000000001</upper>
          <effort>250</effort>
          <velocity>10</velocity>
        </limit>
        <dynamics>
          <spring_reference>0</spring_reference>
          <spring_stiffness>0</spring_stiffness>
        </dynamics>
      </axis>
    </joint>
    <link name='femur_link_3'>
      <pose relative_to='femur_joint_3'>0 0 0 0 0 0</pose>
      <inertial>
        <pose>0 -0.14999999999999999 0.029999999999999999 0 0 0</pose>
        <mass>0.501</mass>
        <inertia>
          <ixx>0.003761674999999999</ixx>
          <ixy>0</ixy>
          <ixz>0</ixz>
          <iyy>4.1749999999999998e-05</iyy>
          <iyz>0</iyz>
          <izz>0.0037950749999999989</izz>
        </inertia>
      </inertial>
      <collision name='femur_link_3_collision'>
        <pose>0 -0.14999999999999999 0.029999999999999999 0 0 0</pose>
        <geometry>
          <box>
            <size>0.029999999999999999 0.29999999999999999 0.01</size>
          </box>
        </geometry>
        <surface>
          <contact>
            <ode/>
          </contact>
          <friction>
            <ode/>
          </friction>
        </surface>
      </collision>
      <visual name='femur_link_3_visual'>
        <pose>0 -0.14999999999999999 0.029999999999999999 0 0 0</pose>
        <geometry>
          <box>
            <size>0.029999999999999999 0.29999999999999999 0.01</size>
          </box>
        </geometry>
        <material>
          <script>
            <name>Gazebo/Orange</name>
            <uri>file://media/materials/scripts/gazebo.material</uri>
          </script>
          <diffuse>1 0.37500003 0.125 1</diffuse>
          <ambient>1 0.37500003 0.125 1</ambient>
        </material>
      </visual>
    </link>
    <joint name='tibia_joint_3' type='revolute'>
      <pose relative_to='femur_link_3'>0 -0.29999999999999999 0.01 3.1415926535897931 0.001592653589793114 3.1415926535897931</pose>
      <parent>femur_link_3</parent>
      <child>tibia_link_3</child>
      <axis>
        <xyz>0 0 1</xyz>
        <limit>
          <lower>-3.1400000000000001</lower>
          <upper>3.1400000000000001</upper>
          <effort>250</effort>
          <velocity>10</velocity>
        </limit>
        <dynamics>
          <spring_reference>0</spring_reference>
          <spring_stiffness>0</spring_stiffness>
        </dynamics>
      </axis>
    </joint>
    <link name='tibia_link_3'>
      <pose relative_to='tibia_joint_3'>0 0 0 0 0 0</pose>
      <inertial>
        <pose>0 -0.15036069651741291 0 0 0 0</pose>
        <mass>0.40200000000000002</mass>
        <inertia>
          <ixx>0.0024606393656716459</ixx>
          <ixy>0</ixy>
          <ixz>0</ixz>
          <iyy>3.3666666666666667e-05</iyy>
          <iyz>0</iyz>
          <izz>0.0024873726990049792</izz>
        </inertia>
      </inertial>
      <collision name='tibia_link_3_collision'>
        <pose>0 -0.14999999999999999 0 0 0 0</pose>
        <geometry>
          <box>
            <size>0.029999999999999999 0.27000000000000002 0.01</size>
          </box>
        </geometry>
        <surface>
          <contact>
            <ode/>
          </contact>
          <friction>
            <ode/>
          </friction>
        </surface>
      </collision>
      <collision name='tibia_link_3_fixed_joint_lump__foot_link_3_collision_1'>
        <pose>0 -0.29499999999999998 0 0 0 0</pose>
        <geometry>
          <sphere>
            <radius>0.025000000000000001</radius>
          </sphere>
        </geometry>
        <surface>
          <contact>
            <ode/>
          </contact>
          <friction>
            <ode/>
          </friction>
        </surface>
      </collision>
      <visual name='tibia_link_3_visual'>
        <pose>0 -0.14999999999999999 0 0 0 0</pose>
        <geometry>
          <box>
            <size>0.029999999999999999 0.27000000000000002 0.01</size>
          </box>
        </geometry>
        <material>
          <script>
            <name>Gazebo/Black</name>
            <uri>file://media/materials/scripts/gazebo.material</uri>
          </script>
          <diffuse>0 0 0 1</diffuse>
          <ambient>0 0 0 1</ambient>
        </material>
      </visual>
      <visual name='tibia_link_3_fixed_joint_lump__foot_link_3_visual_1'>
        <pose>0 -0.29499999999999998 0 0 0 0</pose>
        <geometry>
          <sphere>
            <radius>0.025000000000000001</radius>
          </sphere>
        </geometry>
        <material>
          <script>
            <name>Gazebo/White</name>
            <uri>file://media/materials/scripts/gazebo.material</uri>
          </script>
          <diffuse>1 1 1 1</diffuse>
          <ambient>1 1 1 1</ambient>
        </material>
      </visual>
    </link>
    <joint name='coxa_joint_4' type='revolute'>
      <pose relative_to='base_link'>0 0.20000000000000001 0.25 0 0 3.1400000000000001</pose>
      <parent>base_link</parent>
      <child>coxa_link_4</child>
      <axis>
        <xyz>0 0 1</xyz>
        <limit>
          <lower>-3.1400000000000001</lower>
          <upper>3.1400000000000001</upper>
          <effort>250</effort>
          <velocity>10</velocity>
        </limit>
        <dynamics>
          <spring_reference>0</spring_reference>
          <spring_stiffness>0</spring_stiffness>
        </dynamics>
      </axis>
    </joint>
    <link name='coxa_link_4'>
      <pose relative_to='coxa_joint_4'>0 0 0 0 0 0</pose>
      <inertial>
        <pose>-0.029999999999999999 -0.050000000000000003 -0.050000000000000003 0 1.5700000000004057 0</pose>
        <mass>0.30099999999999999</mass>
        <inertia>
          <ixx>0.00043895833333333341</ixx>
          <ixy>0</ixy>
          <ixz>0</ixz>
          <iyy>0.00043895833333333341</iyy>
          <iyz>0</iyz>
          <izz>0.00037625000000000012</izz>
        </inertia>
      </inertial>
      <collision name='coxa_link_4_collision'>
        <pose>-0.029999999999999999 -0.050000000000000003 -0.050000000000000003 0 1.5707963267948966 0</pose>
        <geometry>
          <cylinder>
            <length>0.10000000000000001</length>
            <radius>0.050000000000000003</radius>
          </cylinder>
        </geometry>
        <surface>
          <contact>
            <ode/>
          </contact>
          <friction>
            <ode/>
          </friction>
        </surface>
      </collision>
      <visual name='coxa_link_4_visual'>
        <pose>-0.029999999999999999 -0.050000000000000003 -0.050000000000000003 0 1.5707963267948966 0</pose>
        <geometry>
          <cylinder>
            <length>0.10000000000000001</length>
            <radius>0.050000000000000003</radius>
          </cylinder>
        </geometry>
        <material>
          <script>
            <name>Gazebo/Blue</name>
            <uri>file://media/materials/scripts/gazebo.material</uri>
          </script>
          <diffuse>1 0 0 1</diffuse>
          <ambient>1 0 0 1</ambient>
        </material>
      </visual>
    </link>
    <joint name='femur_joint_4' type='revolute'>
      <pose relative_to='coxa_link_4'>-0.070000000000000007 -0.050000000000000003 -0.050000000000000003 0 -1.5700000000004057 0</pose>
      <parent>coxa_link_4</parent>
      <child>femur_link_4</child>
      <axis>
        <xyz>0 0 1</xyz>
        <limit>
          <lower>-3.1400000000000001</lower>
          <upper>3.1400000000000001</upper>
          <effort>250</effort>
          <velocity>10</velocity>
        </limit>
        <dynamics>
          <spring_reference>0</spring_reference>
          <spring_stiffness>0</spring_stiffness>
        </dynamics>
      </axis>
    </joint>
    <link name='femur_link_4'>
      <pose relative_to='femur_joint_4'>0 0 0 0 0 0</pose>
      <inertial>
        <pose>0 -0.14999999999999999 0.029999999999999999 0 0 0</pose>
        <mass>0.501</mass>
        <inertia>
          <ixx>0.003761674999999999</ixx>
          <ixy>0</ixy>
          <ixz>0</ixz>
          <iyy>4.1749999999999998e-05</iyy>
          <iyz>0</iyz>
          <izz>0.0037950749999999989</izz>
        </inertia>
      </inertial>
      <collision name='femur_link_4_collision'>
        <pose>0 -0.14999999999999999 0.029999999999999999 0 0 0</pose>
        <geometry>
          <box>
            <size>0.029999999999999999 0.29999999999999999 0.01</size>
          </box>
        </geometry>
        <surface>
          <contact>
            <ode/>
          </contact>
          <friction>
            <ode/>
          </friction>
        </surface>
      </collision>
      <visual name='femur_link_4_visual'>
        <pose>0 -0.14999999999999999 0.029999999999999999 0 0 0</pose>
        <geometry>
          <box>
            <size>0.029999999999999999 0.29999999999999999 0.01</size>
          </box>
        </geometry>
        <material>
          <script>
            <name>Gazebo/Orange</name>
            <uri>file://media/materials/scripts/gazebo.material</uri>
          </script>
          <diffuse>1 0.37500003 0.125 1</diffuse>
          <ambient>1 0.37500003 0.125 1</ambient>
        </material>
      </visual>
    </link>
    <joint name='tibia_joint_4' type='revolute'>
      <pose relative_to='femur_link_4'>0 -0.29999999999999999 0.01 3.1415926535897931 0.001592653589793114 3.1415926535897931</pose>
      <parent>femur_link_4</parent>
      <child>tibia_link_4</child>
      <axis>
        <xyz>0 0 1</xyz>
        <limit>
          <lower>-3.1400000000000001</lower>
          <upper>3.1400000000000001</upper>
          <effort>250</effort>
          <velocity>10</velocity>
        </limit>
        <dynamics>
          <spring_reference>0</spring_reference>
          <spring_stiffness>0</spring_stiffness>
        </dynamics>
      </axis>
    </joint>
    <link name='tibia_link_4'>
      <pose relative_to='tibia_joint_4'>0 0 0 0 0 0</pose>
      <inertial>
        <pose>0 -0.15036069651741291 0 0 0 0</pose>
        <mass>0.40200000000000002</mass>
        <inertia>
          <ixx>0.0024606393656716459</ixx>
          <ixy>0</ixy>
          <ixz>0</ixz>
          <iyy>3.3666666666666667e-05</iyy>
          <iyz>0</iyz>
          <izz>0.0024873726990049792</izz>
        </inertia>
      </inertial>
      <collision name='tibia_link_4_collision'>
        <pose>0 -0.14999999999999999 0 0 0 0</pose>
        <geometry>
          <box>
            <size>0.029999999999999999 0.27000000000000002 0.01</size>
          </box>
        </geometry>
        <surface>
          <contact>
            <ode/>
          </contact>
          <friction>
            <ode/>
          </friction>
        </surface>
      </collision>
      <collision name='tibia_link_4_fixed_joint_lump__foot_link_4_collision_1'>
        <pose>0 -0.29499999999999998 0 0 0 0</pose>
        <geometry>
          <sphere>
            <radius>0.025000000000000001</radius>
          </sphere>
        </geometry>
        <surface>
          <contact>
            <ode/>
          </contact>
          <friction>
            <ode/>
          </friction>
        </surface>
      </collision>
      <visual name='tibia_link_4_visual'>
        <pose>0 -0.14999999999999999 0 0 0 0</pose>
        <geometry>
          <box>
            <size>0.029999999999999999 0.27000000000000002 0.01</size>
          </box>
        </geometry>
        <material>
          <script>
            <name>Gazebo/Black</name>
            <uri>file://media/materials/scripts/gazebo.material</uri>
          </script>
          <diffuse>0 0 0 1</diffuse>
          <ambient>0 0 0 1</ambient>
        </material>
      </visual>
      <visual name='tibia_link_4_fixed_joint_lump__foot_link_4_visual_1'>
        <pose>0 -0.29499999999999998 0 0 0 0</pose>
        <geometry>
          <sphere>
            <radius>0.025000000000000001</radius>
          </sphere>
        </geometry>
        <material>
          <script>
            <name>Gazebo/White</name>
            <uri>file://media/materials/scripts/gazebo.material</uri>
          </script>
          <diffuse>1 1 1 1</diffuse>
          <ambient>1 1 1 1</ambient>
        </material>
      </visual>
    </link>
    <joint name='coxa_joint_5' type='revolute'>
      <pose relative_to='base_link'>-0.27500000000000002 0.20000000000000001 0.25 0 0 3.1400000000000001</pose>
      <parent>base_link</parent>
      <child>coxa_link_5</child>
      <axis>
        <xyz>0 0 1</xyz>
        <limit>
          <lower>-3.1400000000000001</lower>
          <upper>3.1400000000000001</upper>
          <effort>250</effort>
          <velocity>10</velocity>
        </limit>
        <dynamics>
          <spring_reference>0</spring_reference>
          <spring_stiffness>0</spring_stiffness>
        </dynamics>
      </axis>
    </joint>
    <link name='coxa_link_5'>
      <pose relative_to='coxa_joint_5'>0 0 0 0 0 0</pose>
      <inertial>
        <pose>0.029999999999999999 -0.050000000000000003 -0.050000000000000003 0 1.5700000000004057 0</pose>
        <mass>0.30099999999999999</mass>
        <inertia>
          <ixx>0.00043895833333333341</ixx>
          <ixy>0</ixy>
          <ixz>0</ixz>
          <iyy>0.00043895833333333341</iyy>
          <iyz>0</iyz>
          <izz>0.00037625000000000012</izz>
        </inertia>
      </inertial>
      <collision name='coxa_link_5_collision'>
        <pose>0.029999999999999999 -0.050000000000000003 -0.050000000000000003 0 1.5707963267948966 0</pose>
        <geometry>
          <cylinder>
            <length>0.10000000000000001</length>
            <radius>0.050000000000000003</radius>
          </cylinder>
        </geometry>
        <surface>
          <contact>
            <ode/>
          </contact>
          <friction>
            <ode/>
          </friction>
        </surface>
      </collision>
      <visual name='coxa_link_5_visual'>
        <pose>0.029999999999999999 -0.050000000000000003 -0.050000000000000003 0 1.5707963267948966 0</pose>
        <geometry>
          <cylinder>
            <length>0.10000000000000001</length>
            <radius>0.050000000000000003</radius>
          </cylinder>
        </geometry>
        <material>
          <script>
            <name>Gazebo/Blue</name>
            <uri>file://media/materials/scripts/gazebo.material</uri>
          </script>
          <diffuse>1 0 0 1</diffuse>
          <ambient>1 0 0 1</ambient>
        </material>
      </visual>
    </link>
    <joint name='femur_joint_5' type='revolute'>
      <pose relative_to='coxa_link_5'>0.070000000000000007 -0.050000000000000003 -0.050000000000000003 0 -1.5700000000004057 0</pose>
      <parent>coxa_link_5</parent>
      <child>femur_link_5</child>
      <axis>
        <xyz>0 0 1</xyz>
        <limit>
          <lower>-3.1400000000000001</lower>
          <upper>3.1400000000000001</upper>
          <effort>250</effort>
          <velocity>10</velocity>
        </limit>
        <dynamics>
          <spring_reference>0</spring_reference>
          <spring_stiffness>0</spring_stiffness>
        </dynamics>
      </axis>
    </joint>
    <link name='femur_link_5'>
      <pose relative_to='femur_joint_5'>0 0 0 0 0 0</pose>
      <inertial>
        <pose>0 -0.14999999999999999 -0.029999999999999999 0 0 0</pose>
        <mass>0.501</mass>
        <inertia>
          <ixx>0.003761674999999999</ixx>
          <ixy>0</ixy>
          <ixz>0</ixz>
          <iyy>4.1749999999999998e-05</iyy>
          <iyz>0</iyz>
          <izz>0.0037950749999999989</izz>
        </inertia>
      </inertial>
      <collision name='femur_link_5_collision'>
        <pose>0 -0.14999999999999999 -0.029999999999999999 0 0 0</pose>
        <geometry>
          <box>
            <size>0.029999999999999999 0.29999999999999999 0.01</size>
          </box>
        </geometry>
        <surface>
          <contact>
            <ode/>
          </contact>
          <friction>
            <ode/>
          </friction>
        </surface>
      </collision>
      <visual name='femur_link_5_visual'>
        <pose>0 -0.14999999999999999 -0.029999999999999999 0 0 0</pose>
        <geometry>
          <box>
            <size>0.029999999999999999 0.29999999999999999 0.01</size>
          </box>
        </geometry>
        <material>
          <script>
            <name>Gazebo/Orange</name>
            <uri>file://media/materials/scripts/gazebo.material</uri>
          </script>
          <diffuse>1 0.37500003 0.125 1</diffuse>
          <ambient>1 0.37500003 0.125 1</ambient>
        </material>
      </visual>
    </link>
    <joint name='tibia_joint_5' type='revolute'>
      <pose relative_to='femur_link_5'>0 -0.29999999999999999 -0.01 3.1415926535897931 0.001592653589793114 3.1415926535897931</pose>
      <parent>femur_link_5</parent>
      <child>tibia_link_5</child>
      <axis>
        <xyz>0 0 1</xyz>
        <limit>
          <lower>-3.1400000000000001</lower>
          <upper>3.1400000000000001</upper>
          <effort>250</effort>
          <velocity>10</velocity>
        </limit>
        <dynamics>
          <spring_reference>0</spring_reference>
          <spring_stiffness>0</spring_stiffness>
        </dynamics>
      </axis>
    </joint>
    <link name='tibia_link_5'>
      <pose relative_to='tibia_joint_5'>0 0 0 0 0 0</pose>
      <inertial>
        <pose>0 -0.15036069651741291 0 0 0 0</pose>
        <mass>0.40200000000000002</mass>
        <inertia>
          <ixx>0.0024606393656716459</ixx>
          <ixy>0</ixy>
          <ixz>0</ixz>
          <iyy>3.3666666666666667e-05</iyy>
          <iyz>0</iyz>
          <izz>0.0024873726990049792</izz>
        </inertia>
      </inertial>
      <collision name='tibia_link_5_collision'>
        <pose>0 -0.14999999999999999 0 0 0 0</pose>
        <geometry>
          <box>
            <size>0.029999999999999999 0.27000000000000002 0.01</size>
          </box>
        </geometry>
        <surface>
          <contact>
            <ode/>
          </contact>
          <friction>
            <ode/>
          </friction>
        </surface>
      </collision>
      <collision name='tibia_link_5_fixed_joint_lump__foot_link_5_collision_1'>
        <pose>0 -0.29499999999999998 0 0 0 0</pose>
        <geometry>
          <sphere>
            <radius>0.025000000000000001</radius>
          </sphere>
        </geometry>
        <surface>
          <contact>
            <ode/>
          </contact>
          <friction>
            <ode/>
          </friction>
        </surface>
      </collision>
      <visual name='tibia_link_5_visual'>
        <pose>0 -0.14999999999999999 0 0 0 0</pose>
        <geometry>
          <box>
            <size>0.029999999999999999 0.27000000000000002 0.01</size>
          </box>
        </geometry>
        <material>
          <script>
            <name>Gazebo/Black</name>
            <uri>file://media/materials/scripts/gazebo.material</uri>
          </script>
          <diffuse>0 0 0 1</diffuse>
          <ambient>0 0 0 1</ambient>
        </material>
      </visual>
      <visual name='tibia_link_5_fixed_joint_lump__foot_link_5_visual_1'>
        <pose>0 -0.29499999999999998 0 0 0 0</pose>
        <geometry>
          <sphere>
            <radius>0.025000000000000001</radius>
          </sphere>
        </geometry>
        <material>
          <script>
            <name>Gazebo/White</name>
            <uri>file://media/materials/scripts/gazebo.material</uri>
          </script>
          <diffuse>1 1 1 1</diffuse>
          <ambient>1 1 1 1</ambient>
        </material>
      </visual>
    </link>
    <plugin name='gz_ros2_control::GazeboSimROS2ControlPlugin' filename='libgz_ros2_control-system.so'>
      <robot_param>robot_description</robot_param>
      <robot_param_node>robot_state_publisher</robot_param_node>
      <parameters>/home/jorge/Documents/Code/silver2_gz/install/silver/share/silver/config/silver_controllers.yaml</parameters>
    </plugin>
    <frame name='body_joint' attached_to='base_link'>
      <pose>0 0 0.40000000000000002 0 0 0</pose>
    </frame>
    <frame name='body_link' attached_to='body_joint'>
      <pose>0 0 0 0 0 0</pose>
    </frame>
    <frame name='foot_joint_0' attached_to='tibia_link_0'>
      <pose>0 -0.29499999999999998 0 0 0 0</pose>
    </frame>
    <frame name='foot_link_0' attached_to='foot_joint_0'>
      <pose>0 0 0 0 0 0</pose>
    </frame>
    <frame name='foot_joint_1' attached_to='tibia_link_1'>
      <pose>0 -0.29499999999999998 0 0 0 0</pose>
    </frame>
    <frame name='foot_link_1' attached_to='foot_joint_1'>
      <pose>0 0 0 0 0 0</pose>
    </frame>
    <frame name='foot_joint_2' attached_to='tibia_link_2'>
      <pose>0 -0.29499999999999998 0 0 0 0</pose>
    </frame>
    <frame name='foot_link_2' attached_to='foot_joint_2'>
      <pose>0 0 0 0 0 0</pose>
    </frame>
    <frame name='foot_joint_3' attached_to='tibia_link_3'>
      <pose>0 -0.29499999999999998 0 0 0 0</pose>
    </frame>
    <frame name='foot_link_3' attached_to='foot_joint_3'>
      <pose>0 0 0 0 0 0</pose>
    </frame>
    <frame name='foot_joint_4' attached_to='tibia_link_4'>
      <pose>0 -0.29499999999999998 0 0 0 0</pose>
    </frame>
    <frame name='foot_link_4' attached_to='foot_joint_4'>
      <pose>0 0 0 0 0 0</pose>
    </frame>
    <frame name='foot_joint_5' attached_to='tibia_link_5'>
      <pose>0 -0.29499999999999998 0 0 0 0</pose>
    </frame>
    <frame name='foot_link_5' attached_to='foot_joint_5'>
      <pose>0 0 0 0 0 0</pose>
    </frame>
  </model>
</sdf>
