<?xml version="1.0" ?>
<!-- =================================================================================== -->
<!-- |    This document was autogenerated by xacro from silver.xacro                   | -->
<!-- |    EDITING THIS FILE BY HAND IS NOT RECOMMENDED                                 | -->
<!-- =================================================================================== -->
<robot name="robot">
  <gazebo>
    <!-- <plugin filename="gz_ros2_control-system" name="gz_ros2_control::GazeboSimROS2ControlPlugin"> -->
    <!-- <plugin filename="libgazebo_ros2_control.so" name="gazebo_ros2_control"> -->
    <plugin filename="libgz_ros2_control-system.so" name="gz_ros2_control::GazeboSimROS2ControlPlugin">
      <robot_param>robot_description</robot_param>
      <robot_param_node>robot_state_publisher</robot_param_node>
      <parameters>/home/jorge/Documents/Code/silver2_gz/install/silver/share/silver/config/silver_controllers.yaml</parameters>
    </plugin>
  </gazebo>
  <ros2_control name="SilverSystem" type="system">
    <hardware>
      <plugin>gz_ros2_control/GazeboSimSystem</plugin>
    </hardware>
    <joint name="coxa_joint_0">
      <param name="id">0</param>
      <param name="pos_kp">5000</param>
      <param name="pos_ki">1</param>
      <param name="pos_kd">3</param>
      <param name="pos_max_integral_error">10000</param>
      <param name="min">-3.14</param>
      <param name="max">3.14</param>
      <command_interface name="position"/>
      <command_interface name="position_pid"/>
      <command_interface name="velocity"/>
      <command_interface name="effort"/>
      <!--SET INITIAL POSITION, note that this will not reset when gazebo world is restarted-->
      <state_interface name="position">
        <param name="initial_value">0.75</param>
      </state_interface>
      <state_interface name="velocity"/>
      <state_interface name="effort"/>
    </joint>
    <joint name="femur_joint_0">
      <param name="id">1</param>
      <param name="pos_kp">5000</param>
      <param name="pos_ki">1</param>
      <param name="pos_kd">3</param>
      <param name="pos_max_integral_error">10000</param>
      <param name="min">-3.14</param>
      <param name="max">3.14</param>
      <command_interface name="position"/>
      <command_interface name="position_pid"/>
      <command_interface name="velocity"/>
      <command_interface name="effort"/>
      <state_interface name="position">
        <param name="initial_value">0.8</param>
      </state_interface>
      <state_interface name="velocity"/>
      <state_interface name="effort"/>
    </joint>
    <joint name="tibia_joint_0">
      <param name="id">2</param>
      <param name="pos_kp">5000</param>
      <param name="pos_ki">1</param>
      <param name="pos_kd">3</param>
      <param name="pos_max_integral_error">10000</param>
      <param name="min">-3.14</param>
      <param name="max">3.14</param>
      <command_interface name="position"/>
      <command_interface name="position_pid"/>
      <command_interface name="velocity"/>
      <command_interface name="effort"/>
      <state_interface name="position">
        <param name="initial_value">2.3</param>
      </state_interface>
      <state_interface name="velocity"/>
      <state_interface name="effort"/>
    </joint>
    <joint name="coxa_joint_1">
      <param name="id">3</param>
      <param name="pos_kp">5000</param>
      <param name="pos_ki">1</param>
      <param name="pos_kd">3</param>
      <param name="pos_max_integral_error">10000</param>
      <param name="min">-3.14</param>
      <param name="max">3.14</param>
      <command_interface name="position"/>
      <command_interface name="position_pid"/>
      <command_interface name="velocity"/>
      <command_interface name="effort"/>
      <!--SET INITIAL POSITION, note that this will not reset when gazebo world is restarted-->
      <state_interface name="position">
        <param name="initial_value">0.0</param>
      </state_interface>
      <state_interface name="velocity"/>
      <state_interface name="effort"/>
    </joint>
    <joint name="femur_joint_1">
      <param name="id">4</param>
      <param name="pos_kp">5000</param>
      <param name="pos_ki">1</param>
      <param name="pos_kd">3</param>
      <param name="pos_max_integral_error">10000</param>
      <param name="min">-3.14</param>
      <param name="max">3.14</param>
      <command_interface name="position"/>
      <command_interface name="position_pid"/>
      <command_interface name="velocity"/>
      <command_interface name="effort"/>
      <state_interface name="position">
        <param name="initial_value">0.8</param>
      </state_interface>
      <state_interface name="velocity"/>
      <state_interface name="effort"/>
    </joint>
    <joint name="tibia_joint_1">
      <param name="id">5</param>
      <param name="pos_kp">5000</param>
      <param name="pos_ki">1</param>
      <param name="pos_kd">3</param>
      <param name="pos_max_integral_error">10000</param>
      <param name="min">-3.14</param>
      <param name="max">3.14</param>
      <command_interface name="position"/>
      <command_interface name="position_pid"/>
      <command_interface name="velocity"/>
      <command_interface name="effort"/>
      <state_interface name="position">
        <param name="initial_value">2.3</param>
      </state_interface>
      <state_interface name="velocity"/>
      <state_interface name="effort"/>
    </joint>
    <joint name="coxa_joint_2">
      <param name="id">6</param>
      <param name="pos_kp">5000</param>
      <param name="pos_ki">1</param>
      <param name="pos_kd">3</param>
      <param name="pos_max_integral_error">10000</param>
      <param name="min">-3.14</param>
      <param name="max">3.14</param>
      <command_interface name="position"/>
      <command_interface name="position_pid"/>
      <command_interface name="velocity"/>
      <command_interface name="effort"/>
      <!--SET INITIAL POSITION, note that this will not reset when gazebo world is restarted-->
      <state_interface name="position">
        <param name="initial_value">-0.75</param>
      </state_interface>
      <state_interface name="velocity"/>
      <state_interface name="effort"/>
    </joint>
    <joint name="femur_joint_2">
      <param name="id">7</param>
      <param name="pos_kp">5000</param>
      <param name="pos_ki">1</param>
      <param name="pos_kd">3</param>
      <param name="pos_max_integral_error">10000</param>
      <param name="min">-3.14</param>
      <param name="max">3.14</param>
      <command_interface name="position"/>
      <command_interface name="position_pid"/>
      <command_interface name="velocity"/>
      <command_interface name="effort"/>
      <state_interface name="position">
        <param name="initial_value">0.8</param>
      </state_interface>
      <state_interface name="velocity"/>
      <state_interface name="effort"/>
    </joint>
    <joint name="tibia_joint_2">
      <param name="id">8</param>
      <param name="pos_kp">5000</param>
      <param name="pos_ki">1</param>
      <param name="pos_kd">3</param>
      <param name="pos_max_integral_error">10000</param>
      <param name="min">-3.14</param>
      <param name="max">3.14</param>
      <command_interface name="position"/>
      <command_interface name="position_pid"/>
      <command_interface name="velocity"/>
      <command_interface name="effort"/>
      <state_interface name="position">
        <param name="initial_value">2.3</param>
      </state_interface>
      <state_interface name="velocity"/>
      <state_interface name="effort"/>
    </joint>
    <joint name="coxa_joint_3">
      <param name="id">9</param>
      <param name="pos_kp">5000</param>
      <param name="pos_ki">1</param>
      <param name="pos_kd">3</param>
      <param name="pos_max_integral_error">10000</param>
      <param name="min">-3.14</param>
      <param name="max">3.14</param>
      <command_interface name="position"/>
      <command_interface name="position_pid"/>
      <command_interface name="velocity"/>
      <command_interface name="effort"/>
      <!--SET INITIAL POSITION, note that this will not reset when gazebo world is restarted-->
      <state_interface name="position">
        <param name="initial_value">-0.75</param>
      </state_interface>
      <state_interface name="velocity"/>
      <state_interface name="effort"/>
    </joint>
    <joint name="femur_joint_3">
      <param name="id">10</param>
      <param name="pos_kp">5000</param>
      <param name="pos_ki">1</param>
      <param name="pos_kd">3</param>
      <param name="pos_max_integral_error">10000</param>
      <param name="min">-3.14</param>
      <param name="max">3.14</param>
      <command_interface name="position"/>
      <command_interface name="position_pid"/>
      <command_interface name="velocity"/>
      <command_interface name="effort"/>
      <state_interface name="position">
        <param name="initial_value">0.8</param>
      </state_interface>
      <state_interface name="velocity"/>
      <state_interface name="effort"/>
    </joint>
    <joint name="tibia_joint_3">
      <param name="id">11</param>
      <param name="pos_kp">5000</param>
      <param name="pos_ki">1</param>
      <param name="pos_kd">3</param>
      <param name="pos_max_integral_error">10000</param>
      <param name="min">-3.14</param>
      <param name="max">3.14</param>
      <command_interface name="position"/>
      <command_interface name="position_pid"/>
      <command_interface name="velocity"/>
      <command_interface name="effort"/>
      <state_interface name="position">
        <param name="initial_value">2.3</param>
      </state_interface>
      <state_interface name="velocity"/>
      <state_interface name="effort"/>
    </joint>
    <joint name="coxa_joint_4">
      <param name="id">12</param>
      <param name="pos_kp">5000</param>
      <param name="pos_ki">1</param>
      <param name="pos_kd">3</param>
      <param name="pos_max_integral_error">10000</param>
      <param name="min">-3.14</param>
      <param name="max">3.14</param>
      <command_interface name="position"/>
      <command_interface name="position_pid"/>
      <command_interface name="velocity"/>
      <command_interface name="effort"/>
      <!--SET INITIAL POSITION, note that this will not reset when gazebo world is restarted-->
      <state_interface name="position">
        <param name="initial_value">0.0</param>
      </state_interface>
      <state_interface name="velocity"/>
      <state_interface name="effort"/>
    </joint>
    <joint name="femur_joint_4">
      <param name="id">13</param>
      <param name="pos_kp">5000</param>
      <param name="pos_ki">1</param>
      <param name="pos_kd">3</param>
      <param name="pos_max_integral_error">10000</param>
      <param name="min">-3.14</param>
      <param name="max">3.14</param>
      <command_interface name="position"/>
      <command_interface name="position_pid"/>
      <command_interface name="velocity"/>
      <command_interface name="effort"/>
      <state_interface name="position">
        <param name="initial_value">0.8</param>
      </state_interface>
      <state_interface name="velocity"/>
      <state_interface name="effort"/>
    </joint>
    <joint name="tibia_joint_4">
      <param name="id">14</param>
      <param name="pos_kp">5000</param>
      <param name="pos_ki">1</param>
      <param name="pos_kd">3</param>
      <param name="pos_max_integral_error">10000</param>
      <param name="min">-3.14</param>
      <param name="max">3.14</param>
      <command_interface name="position"/>
      <command_interface name="position_pid"/>
      <command_interface name="velocity"/>
      <command_interface name="effort"/>
      <state_interface name="position">
        <param name="initial_value">2.3</param>
      </state_interface>
      <state_interface name="velocity"/>
      <state_interface name="effort"/>
    </joint>
    <joint name="coxa_joint_5">
      <param name="id">15</param>
      <param name="pos_kp">5000</param>
      <param name="pos_ki">1</param>
      <param name="pos_kd">3</param>
      <param name="pos_max_integral_error">10000</param>
      <param name="min">-3.14</param>
      <param name="max">3.14</param>
      <command_interface name="position"/>
      <command_interface name="position_pid"/>
      <command_interface name="velocity"/>
      <command_interface name="effort"/>
      <!--SET INITIAL POSITION, note that this will not reset when gazebo world is restarted-->
      <state_interface name="position">
        <param name="initial_value">0.75</param>
      </state_interface>
      <state_interface name="velocity"/>
      <state_interface name="effort"/>
    </joint>
    <joint name="femur_joint_5">
      <param name="id">16</param>
      <param name="pos_kp">5000</param>
      <param name="pos_ki">1</param>
      <param name="pos_kd">3</param>
      <param name="pos_max_integral_error">10000</param>
      <param name="min">-3.14</param>
      <param name="max">3.14</param>
      <command_interface name="position"/>
      <command_interface name="position_pid"/>
      <command_interface name="velocity"/>
      <command_interface name="effort"/>
      <state_interface name="position">
        <param name="initial_value">0.8</param>
      </state_interface>
      <state_interface name="velocity"/>
      <state_interface name="effort"/>
    </joint>
    <joint name="tibia_joint_5">
      <param name="id">17</param>
      <param name="pos_kp">5000</param>
      <param name="pos_ki">1</param>
      <param name="pos_kd">3</param>
      <param name="pos_max_integral_error">10000</param>
      <param name="min">-3.14</param>
      <param name="max">3.14</param>
      <command_interface name="position"/>
      <command_interface name="position_pid"/>
      <command_interface name="velocity"/>
      <command_interface name="effort"/>
      <state_interface name="position">
        <param name="initial_value">2.3</param>
      </state_interface>
      <state_interface name="velocity"/>
      <state_interface name="effort"/>
    </joint>
  </ros2_control>
  <!-- Specify some standard inertial calculations https://en.wikipedia.org/wiki/List_of_moments_of_inertia -->
  <!-- These make use of xacro's mathematical functionality -->
  <!-- m -->
  <!-- m -->
  <!-- m -->
  <!-- m -->
  <!-- m -->
  <!-- Define colors for RVIZ -->
  <material name="white">
    <color rgba="1 1 1 1"/>
  </material>
  <material name="orange">
    <color rgba="1 0.3 0.1 1"/>
  </material>
  <material name="blue">
    <color rgba="0.2 0.2 1 1"/>
  </material>
  <material name="black">
    <color rgba="0 0 0 1"/>
  </material>
  <material name="red">
    <color rgba="1 0 0 1"/>
  </material>
  <!-- BASE LINK -->
  <link name="base_link"/>
  <!-- BODY JOINT AND LINK -->
  <joint name="body_joint" type="fixed">
    <origin rpy="0.0 0.0 0.0" xyz="0.0 0.0 0.4"/>
    <parent link="base_link"/>
    <child link="body_link"/>
  </joint>
  <link name="body_link">
    <visual>
      <origin rpy="1.57 0.0 0.0" xyz="0.0 0.0 0.0"/>
      <geometry>
        <mesh filename="file://models/silver2/meshes/SILVER2_Body.fbx" scale="0.15 0.15 0.15"/>
        <!--<box size="0.55 0.4 0.3"/>-->
      </geometry>
      <!--<material name="blue"/>-->
    </visual>
    <collision>
      <origin rpy="0.0 0.0 0.0" xyz="0.0 0.0 0.0"/>
      <geometry>
        <box size="0.55 0.4 0.3"/>
      </geometry>
    </collision>
    <inertial>
      <origin xyz="0.0 0 0.0"/>
      <mass value="140.0"/>
      <inertia ixx="2.9166666666666665" ixy="0.0" ixz="0.0" iyy="4.5791666666666675" iyz="0.0" izz="5.395833333333334"/>
    </inertial>
  </link>
  <gazebo reference="body_link">
    <material>Gazebo/Blue</material>
  </gazebo>
  <!-- COXA JOINT AND LINK-->
  <joint name="coxa_joint_0" type="revolute">
    <origin rpy="0.0 0.0 0.0" xyz="0.275 -0.2 -0.15"/>
    <parent link="body_link"/>
    <child link="coxa_link_0"/>
    <limit effort="250.0" lower="-3.14" upper="3.14" velocity="10.0"/>
    <axis xyz="0 0 1"/>
    <!--dynamics damping="10.0" friction="10.0"/-->
  </joint>
  <link name="coxa_link_0">
    <visual>
      <origin rpy="0.0 1.57 0.0" xyz="0.03 -0.05 -0.05"/>
      <geometry>
        <cylinder length="0.1" radius="0.05"/>
      </geometry>
      <material name="red"/>
    </visual>
    <collision>
      <origin rpy="0.0 1.57 0.0" xyz="0.03 -0.05 -0.05"/>
      <geometry>
        <cylinder length="0.1" radius="0.05"/>
      </geometry>
    </collision>
    <inertial>
      <origin rpy="0.0 1.57 0.0" xyz="0.03 -0.05 -0.05"/>
      <mass value="0.301"/>
      <inertia ixx="0.00043895833333333336" ixy="0.0" ixz="0.0" iyy="0.00043895833333333336" iyz="0.0" izz="0.00037625000000000007"/>
    </inertial>
  </link>
  <gazebo reference="coxa_link_0">
    <material>Gazebo/Blue</material>
  </gazebo>
  <!-- FEMUR JOINT AND LINK-->
  <joint name="femur_joint_0" type="revolute">
    <origin rpy="0.0 -1.57 0.0" xyz="0.07 -0.05 -0.05"/>
    <parent link="coxa_link_0"/>
    <child link="femur_link_0"/>
    <limit effort="250.0" lower="-3.14" upper="3.14" velocity="10.0"/>
    <axis xyz="0 0 1"/>
  </joint>
  <link name="femur_link_0">
    <visual>
      <origin rpy="0.0 0.0 0.0" xyz="0.0 -0.15 -0.03"/>
      <geometry>
        <box size="0.03 0.3 0.01"/>
      </geometry>
      <material name="orange"/>
    </visual>
    <collision>
      <origin rpy="0.0 0.0 0.0" xyz="0.0 -0.15 -0.03"/>
      <geometry>
        <box size="0.03 0.3 0.01"/>
      </geometry>
    </collision>
    <inertial>
      <origin rpy="0.0 0.0 0.0" xyz="0.0 -0.15 -0.03"/>
      <mass value="0.501"/>
      <inertia ixx="0.0037616749999999995" ixy="0.0" ixz="0.0" iyy="4.175e-05" iyz="0.0" izz="0.0037950749999999993"/>
    </inertial>
  </link>
  <gazebo reference="femur_link_0">
    <material>Gazebo/Orange</material>
  </gazebo>
  <!-- TIBIA JOINT AND LINK -->
  <joint name="tibia_joint_0" type="revolute">
    <origin rpy="0.0 3.14 0.0" xyz="0.0 -0.3 -0.01"/>
    <parent link="femur_link_0"/>
    <child link="tibia_link_0"/>
    <limit effort="250.0" lower="-3.14" upper="3.14" velocity="10.0"/>
    <axis xyz="0 0 1"/>
  </joint>
  <link name="tibia_link_0">
    <visual>
      <origin rpy="0.0 0.0 0.0" xyz="0.0 -0.15 0.0"/>
      <geometry>
        <box size="0.03 0.27 0.01"/>
      </geometry>
      <material name="black"/>
    </visual>
    <collision>
      <origin rpy="0.0 0.0 0.0" xyz="0.0 -0.15 0.0"/>
      <geometry>
        <box size="0.03 0.27 0.01"/>
      </geometry>
    </collision>
    <inertial>
      <origin rpy="0.0 0.0 0.0" xyz="0.0 -0.15 0.0"/>
      <mass value="0.401"/>
      <inertia ixx="0.002439416666666667" ixy="0.0" ixz="0.0" iyy="3.341666666666667e-05" iyz="0.0" izz="0.00246615"/>
    </inertial>
  </link>
  <gazebo reference="tibia_link_0">
    <material>Gazebo/Black</material>
  </gazebo>
  <!-- FOOT JOINT AND LINK -->
  <joint name="foot_joint_0" type="fixed">
    <origin rpy="0.0 0.0 0.0" xyz="0.0 -0.295 0.0"/>
    <parent link="tibia_link_0"/>
    <child link="foot_link_0"/>
  </joint>
  <link name="foot_link_0">
    <visual>
      <origin rpy="0.0 0.0 0.0" xyz="0.0 0.0 0.0"/>
      <geometry>
        <sphere radius="0.025"/>
      </geometry>
      <material name="white"/>
    </visual>
    <collision>
      <origin rpy="0.0 0.0 0.0" xyz="0.0 0.0 0.0"/>
      <geometry>
        <sphere radius="0.025"/>
      </geometry>
    </collision>
    <inertial>
      <origin rpy="0.0 0.0 0.0" xyz="0.0 0.0 0.0"/>
      <mass value="0.001"/>
      <inertia ixx="2.5000000000000004e-07" ixy="0.0" ixz="0.0" iyy="2.5000000000000004e-07" iyz="0.0" izz="2.5000000000000004e-07"/>
    </inertial>
  </link>
  <gazebo reference="foot_link_0">
    <material>Gazebo/White</material>
  </gazebo>
  <!-- COXA JOINT AND LINK-->
  <joint name="coxa_joint_1" type="revolute">
    <origin rpy="0.0 0.0 0.0" xyz="0.0 -0.2 -0.15"/>
    <parent link="body_link"/>
    <child link="coxa_link_1"/>
    <limit effort="250.0" lower="-3.14" upper="3.14" velocity="10.0"/>
    <axis xyz="0 0 1"/>
    <!--dynamics damping="10.0" friction="10.0"/-->
  </joint>
  <link name="coxa_link_1">
    <visual>
      <origin rpy="0.0 1.57 0.0" xyz="0.03 -0.05 -0.05"/>
      <geometry>
        <cylinder length="0.1" radius="0.05"/>
      </geometry>
      <material name="red"/>
    </visual>
    <collision>
      <origin rpy="0.0 1.57 0.0" xyz="0.03 -0.05 -0.05"/>
      <geometry>
        <cylinder length="0.1" radius="0.05"/>
      </geometry>
    </collision>
    <inertial>
      <origin rpy="0.0 1.57 0.0" xyz="0.03 -0.05 -0.05"/>
      <mass value="0.301"/>
      <inertia ixx="0.00043895833333333336" ixy="0.0" ixz="0.0" iyy="0.00043895833333333336" iyz="0.0" izz="0.00037625000000000007"/>
    </inertial>
  </link>
  <gazebo reference="coxa_link_1">
    <material>Gazebo/Blue</material>
  </gazebo>
  <!-- FEMUR JOINT AND LINK-->
  <joint name="femur_joint_1" type="revolute">
    <origin rpy="0.0 -1.57 0.0" xyz="0.07 -0.05 -0.05"/>
    <parent link="coxa_link_1"/>
    <child link="femur_link_1"/>
    <limit effort="250.0" lower="-3.14" upper="3.14" velocity="10.0"/>
    <axis xyz="0 0 1"/>
  </joint>
  <link name="femur_link_1">
    <visual>
      <origin rpy="0.0 0.0 0.0" xyz="0.0 -0.15 -0.03"/>
      <geometry>
        <box size="0.03 0.3 0.01"/>
      </geometry>
      <material name="orange"/>
    </visual>
    <collision>
      <origin rpy="0.0 0.0 0.0" xyz="0.0 -0.15 -0.03"/>
      <geometry>
        <box size="0.03 0.3 0.01"/>
      </geometry>
    </collision>
    <inertial>
      <origin rpy="0.0 0.0 0.0" xyz="0.0 -0.15 -0.03"/>
      <mass value="0.501"/>
      <inertia ixx="0.0037616749999999995" ixy="0.0" ixz="0.0" iyy="4.175e-05" iyz="0.0" izz="0.0037950749999999993"/>
    </inertial>
  </link>
  <gazebo reference="femur_link_1">
    <material>Gazebo/Orange</material>
  </gazebo>
  <!-- TIBIA JOINT AND LINK -->
  <joint name="tibia_joint_1" type="revolute">
    <origin rpy="0.0 3.14 0.0" xyz="0.0 -0.3 -0.01"/>
    <parent link="femur_link_1"/>
    <child link="tibia_link_1"/>
    <limit effort="250.0" lower="-3.14" upper="3.14" velocity="10.0"/>
    <axis xyz="0 0 1"/>
  </joint>
  <link name="tibia_link_1">
    <visual>
      <origin rpy="0.0 0.0 0.0" xyz="0.0 -0.15 0.0"/>
      <geometry>
        <box size="0.03 0.27 0.01"/>
      </geometry>
      <material name="black"/>
    </visual>
    <collision>
      <origin rpy="0.0 0.0 0.0" xyz="0.0 -0.15 0.0"/>
      <geometry>
        <box size="0.03 0.27 0.01"/>
      </geometry>
    </collision>
    <inertial>
      <origin rpy="0.0 0.0 0.0" xyz="0.0 -0.15 0.0"/>
      <mass value="0.401"/>
      <inertia ixx="0.002439416666666667" ixy="0.0" ixz="0.0" iyy="3.341666666666667e-05" iyz="0.0" izz="0.00246615"/>
    </inertial>
  </link>
  <gazebo reference="tibia_link_1">
    <material>Gazebo/Black</material>
  </gazebo>
  <!-- FOOT JOINT AND LINK -->
  <joint name="foot_joint_1" type="fixed">
    <origin rpy="0.0 0.0 0.0" xyz="0.0 -0.295 0.0"/>
    <parent link="tibia_link_1"/>
    <child link="foot_link_1"/>
  </joint>
  <link name="foot_link_1">
    <visual>
      <origin rpy="0.0 0.0 0.0" xyz="0.0 0.0 0.0"/>
      <geometry>
        <sphere radius="0.025"/>
      </geometry>
      <material name="white"/>
    </visual>
    <collision>
      <origin rpy="0.0 0.0 0.0" xyz="0.0 0.0 0.0"/>
      <geometry>
        <sphere radius="0.025"/>
      </geometry>
    </collision>
    <inertial>
      <origin rpy="0.0 0.0 0.0" xyz="0.0 0.0 0.0"/>
      <mass value="0.001"/>
      <inertia ixx="2.5000000000000004e-07" ixy="0.0" ixz="0.0" iyy="2.5000000000000004e-07" iyz="0.0" izz="2.5000000000000004e-07"/>
    </inertial>
  </link>
  <gazebo reference="foot_link_1">
    <material>Gazebo/White</material>
  </gazebo>
  <!-- COXA JOINT AND LINK-->
  <joint name="coxa_joint_2" type="revolute">
    <origin rpy="0.0 0.0 0.0" xyz="-0.275 -0.2 -0.15"/>
    <parent link="body_link"/>
    <child link="coxa_link_2"/>
    <limit effort="250.0" lower="-3.14" upper="3.14" velocity="10.0"/>
    <axis xyz="0 0 1"/>
    <!--dynamics damping="10.0" friction="10.0"/-->
  </joint>
  <link name="coxa_link_2">
    <visual>
      <origin rpy="0.0 1.57 0.0" xyz="-0.03 -0.05 -0.05"/>
      <geometry>
        <cylinder length="0.1" radius="0.05"/>
      </geometry>
      <material name="red"/>
    </visual>
    <collision>
      <origin rpy="0.0 1.57 0.0" xyz="-0.03 -0.05 -0.05"/>
      <geometry>
        <cylinder length="0.1" radius="0.05"/>
      </geometry>
    </collision>
    <inertial>
      <origin rpy="0.0 1.57 0.0" xyz="-0.03 -0.05 -0.05"/>
      <mass value="0.301"/>
      <inertia ixx="0.00043895833333333336" ixy="0.0" ixz="0.0" iyy="0.00043895833333333336" iyz="0.0" izz="0.00037625000000000007"/>
    </inertial>
  </link>
  <gazebo reference="coxa_link_2">
    <material>Gazebo/Blue</material>
  </gazebo>
  <!-- FEMUR JOINT AND LINK-->
  <joint name="femur_joint_2" type="revolute">
    <origin rpy="0.0 -1.57 0.0" xyz="-0.07 -0.05 -0.05"/>
    <parent link="coxa_link_2"/>
    <child link="femur_link_2"/>
    <limit effort="250.0" lower="-3.14" upper="3.14" velocity="10.0"/>
    <axis xyz="0 0 1"/>
  </joint>
  <link name="femur_link_2">
    <visual>
      <origin rpy="0.0 0.0 0.0" xyz="0.0 -0.15 0.03"/>
      <geometry>
        <box size="0.03 0.3 0.01"/>
      </geometry>
      <material name="orange"/>
    </visual>
    <collision>
      <origin rpy="0.0 0.0 0.0" xyz="0.0 -0.15 0.03"/>
      <geometry>
        <box size="0.03 0.3 0.01"/>
      </geometry>
    </collision>
    <inertial>
      <origin rpy="0.0 0.0 0.0" xyz="0.0 -0.15 0.03"/>
      <mass value="0.501"/>
      <inertia ixx="0.0037616749999999995" ixy="0.0" ixz="0.0" iyy="4.175e-05" iyz="0.0" izz="0.0037950749999999993"/>
    </inertial>
  </link>
  <gazebo reference="femur_link_2">
    <material>Gazebo/Orange</material>
  </gazebo>
  <!-- TIBIA JOINT AND LINK -->
  <joint name="tibia_joint_2" type="revolute">
    <origin rpy="0.0 3.14 0.0" xyz="0.0 -0.3 0.01"/>
    <parent link="femur_link_2"/>
    <child link="tibia_link_2"/>
    <limit effort="250.0" lower="-3.14" upper="3.14" velocity="10.0"/>
    <axis xyz="0 0 1"/>
  </joint>
  <link name="tibia_link_2">
    <visual>
      <origin rpy="0.0 0.0 0.0" xyz="0.0 -0.15 0.0"/>
      <geometry>
        <box size="0.03 0.27 0.01"/>
      </geometry>
      <material name="black"/>
    </visual>
    <collision>
      <origin rpy="0.0 0.0 0.0" xyz="0.0 -0.15 0.0"/>
      <geometry>
        <box size="0.03 0.27 0.01"/>
      </geometry>
    </collision>
    <inertial>
      <origin rpy="0.0 0.0 0.0" xyz="0.0 -0.15 0.0"/>
      <mass value="0.401"/>
      <inertia ixx="0.002439416666666667" ixy="0.0" ixz="0.0" iyy="3.341666666666667e-05" iyz="0.0" izz="0.00246615"/>
    </inertial>
  </link>
  <gazebo reference="tibia_link_2">
    <material>Gazebo/Black</material>
  </gazebo>
  <!-- FOOT JOINT AND LINK -->
  <joint name="foot_joint_2" type="fixed">
    <origin rpy="0.0 0.0 0.0" xyz="0.0 -0.295 0.0"/>
    <parent link="tibia_link_2"/>
    <child link="foot_link_2"/>
  </joint>
  <link name="foot_link_2">
    <visual>
      <origin rpy="0.0 0.0 0.0" xyz="0.0 0.0 0.0"/>
      <geometry>
        <sphere radius="0.025"/>
      </geometry>
      <material name="white"/>
    </visual>
    <collision>
      <origin rpy="0.0 0.0 0.0" xyz="0.0 0.0 0.0"/>
      <geometry>
        <sphere radius="0.025"/>
      </geometry>
    </collision>
    <inertial>
      <origin rpy="0.0 0.0 0.0" xyz="0.0 0.0 0.0"/>
      <mass value="0.001"/>
      <inertia ixx="2.5000000000000004e-07" ixy="0.0" ixz="0.0" iyy="2.5000000000000004e-07" iyz="0.0" izz="2.5000000000000004e-07"/>
    </inertial>
  </link>
  <gazebo reference="foot_link_2">
    <material>Gazebo/White</material>
  </gazebo>
  <!-- COXA JOINT AND LINK-->
  <joint name="coxa_joint_3" type="revolute">
    <origin rpy="0.0 0.0 3.14" xyz="0.275 0.2 -0.15"/>
    <parent link="body_link"/>
    <child link="coxa_link_3"/>
    <limit effort="250.0" lower="-3.14" upper="3.14" velocity="10.0"/>
    <axis xyz="0 0 1"/>
    <!--dynamics damping="10.0" friction="10.0"/-->
  </joint>
  <link name="coxa_link_3">
    <visual>
      <origin rpy="0.0 1.57 0.0" xyz="-0.03 -0.05 -0.05"/>
      <geometry>
        <cylinder length="0.1" radius="0.05"/>
      </geometry>
      <material name="red"/>
    </visual>
    <collision>
      <origin rpy="0.0 1.57 0.0" xyz="-0.03 -0.05 -0.05"/>
      <geometry>
        <cylinder length="0.1" radius="0.05"/>
      </geometry>
    </collision>
    <inertial>
      <origin rpy="0.0 1.57 0.0" xyz="-0.03 -0.05 -0.05"/>
      <mass value="0.301"/>
      <inertia ixx="0.00043895833333333336" ixy="0.0" ixz="0.0" iyy="0.00043895833333333336" iyz="0.0" izz="0.00037625000000000007"/>
    </inertial>
  </link>
  <gazebo reference="coxa_link_3">
    <material>Gazebo/Blue</material>
  </gazebo>
  <!-- FEMUR JOINT AND LINK-->
  <joint name="femur_joint_3" type="revolute">
    <origin rpy="0.0 -1.57 0.0" xyz="-0.07 -0.05 -0.05"/>
    <parent link="coxa_link_3"/>
    <child link="femur_link_3"/>
    <limit effort="250.0" lower="-3.14" upper="3.14" velocity="10.0"/>
    <axis xyz="0 0 1"/>
  </joint>
  <link name="femur_link_3">
    <visual>
      <origin rpy="0.0 0.0 0.0" xyz="0.0 -0.15 0.03"/>
      <geometry>
        <box size="0.03 0.3 0.01"/>
      </geometry>
      <material name="orange"/>
    </visual>
    <collision>
      <origin rpy="0.0 0.0 0.0" xyz="0.0 -0.15 0.03"/>
      <geometry>
        <box size="0.03 0.3 0.01"/>
      </geometry>
    </collision>
    <inertial>
      <origin rpy="0.0 0.0 0.0" xyz="0.0 -0.15 0.03"/>
      <mass value="0.501"/>
      <inertia ixx="0.0037616749999999995" ixy="0.0" ixz="0.0" iyy="4.175e-05" iyz="0.0" izz="0.0037950749999999993"/>
    </inertial>
  </link>
  <gazebo reference="femur_link_3">
    <material>Gazebo/Orange</material>
  </gazebo>
  <!-- TIBIA JOINT AND LINK -->
  <joint name="tibia_joint_3" type="revolute">
    <origin rpy="0.0 3.14 0.0" xyz="0.0 -0.3 0.01"/>
    <parent link="femur_link_3"/>
    <child link="tibia_link_3"/>
    <limit effort="250.0" lower="-3.14" upper="3.14" velocity="10.0"/>
    <axis xyz="0 0 1"/>
  </joint>
  <link name="tibia_link_3">
    <visual>
      <origin rpy="0.0 0.0 0.0" xyz="0.0 -0.15 0.0"/>
      <geometry>
        <box size="0.03 0.27 0.01"/>
      </geometry>
      <material name="black"/>
    </visual>
    <collision>
      <origin rpy="0.0 0.0 0.0" xyz="0.0 -0.15 0.0"/>
      <geometry>
        <box size="0.03 0.27 0.01"/>
      </geometry>
    </collision>
    <inertial>
      <origin rpy="0.0 0.0 0.0" xyz="0.0 -0.15 0.0"/>
      <mass value="0.401"/>
      <inertia ixx="0.002439416666666667" ixy="0.0" ixz="0.0" iyy="3.341666666666667e-05" iyz="0.0" izz="0.00246615"/>
    </inertial>
  </link>
  <gazebo reference="tibia_link_3">
    <material>Gazebo/Black</material>
  </gazebo>
  <!-- FOOT JOINT AND LINK -->
  <joint name="foot_joint_3" type="fixed">
    <origin rpy="0.0 0.0 0.0" xyz="0.0 -0.295 0.0"/>
    <parent link="tibia_link_3"/>
    <child link="foot_link_3"/>
  </joint>
  <link name="foot_link_3">
    <visual>
      <origin rpy="0.0 0.0 0.0" xyz="0.0 0.0 0.0"/>
      <geometry>
        <sphere radius="0.025"/>
      </geometry>
      <material name="white"/>
    </visual>
    <collision>
      <origin rpy="0.0 0.0 0.0" xyz="0.0 0.0 0.0"/>
      <geometry>
        <sphere radius="0.025"/>
      </geometry>
    </collision>
    <inertial>
      <origin rpy="0.0 0.0 0.0" xyz="0.0 0.0 0.0"/>
      <mass value="0.001"/>
      <inertia ixx="2.5000000000000004e-07" ixy="0.0" ixz="0.0" iyy="2.5000000000000004e-07" iyz="0.0" izz="2.5000000000000004e-07"/>
    </inertial>
  </link>
  <gazebo reference="foot_link_3">
    <material>Gazebo/White</material>
  </gazebo>
  <!-- COXA JOINT AND LINK-->
  <joint name="coxa_joint_4" type="revolute">
    <origin rpy="0.0 0.0 3.14" xyz="0.0 0.2 -0.15"/>
    <parent link="body_link"/>
    <child link="coxa_link_4"/>
    <limit effort="250.0" lower="-3.14" upper="3.14" velocity="10.0"/>
    <axis xyz="0 0 1"/>
    <!--dynamics damping="10.0" friction="10.0"/-->
  </joint>
  <link name="coxa_link_4">
    <visual>
      <origin rpy="0.0 1.57 0.0" xyz="-0.03 -0.05 -0.05"/>
      <geometry>
        <cylinder length="0.1" radius="0.05"/>
      </geometry>
      <material name="red"/>
    </visual>
    <collision>
      <origin rpy="0.0 1.57 0.0" xyz="-0.03 -0.05 -0.05"/>
      <geometry>
        <cylinder length="0.1" radius="0.05"/>
      </geometry>
    </collision>
    <inertial>
      <origin rpy="0.0 1.57 0.0" xyz="-0.03 -0.05 -0.05"/>
      <mass value="0.301"/>
      <inertia ixx="0.00043895833333333336" ixy="0.0" ixz="0.0" iyy="0.00043895833333333336" iyz="0.0" izz="0.00037625000000000007"/>
    </inertial>
  </link>
  <gazebo reference="coxa_link_4">
    <material>Gazebo/Blue</material>
  </gazebo>
  <!-- FEMUR JOINT AND LINK-->
  <joint name="femur_joint_4" type="revolute">
    <origin rpy="0.0 -1.57 0.0" xyz="-0.07 -0.05 -0.05"/>
    <parent link="coxa_link_4"/>
    <child link="femur_link_4"/>
    <limit effort="250.0" lower="-3.14" upper="3.14" velocity="10.0"/>
    <axis xyz="0 0 1"/>
  </joint>
  <link name="femur_link_4">
    <visual>
      <origin rpy="0.0 0.0 0.0" xyz="0.0 -0.15 0.03"/>
      <geometry>
        <box size="0.03 0.3 0.01"/>
      </geometry>
      <material name="orange"/>
    </visual>
    <collision>
      <origin rpy="0.0 0.0 0.0" xyz="0.0 -0.15 0.03"/>
      <geometry>
        <box size="0.03 0.3 0.01"/>
      </geometry>
    </collision>
    <inertial>
      <origin rpy="0.0 0.0 0.0" xyz="0.0 -0.15 0.03"/>
      <mass value="0.501"/>
      <inertia ixx="0.0037616749999999995" ixy="0.0" ixz="0.0" iyy="4.175e-05" iyz="0.0" izz="0.0037950749999999993"/>
    </inertial>
  </link>
  <gazebo reference="femur_link_4">
    <material>Gazebo/Orange</material>
  </gazebo>
  <!-- TIBIA JOINT AND LINK -->
  <joint name="tibia_joint_4" type="revolute">
    <origin rpy="0.0 3.14 0.0" xyz="0.0 -0.3 0.01"/>
    <parent link="femur_link_4"/>
    <child link="tibia_link_4"/>
    <limit effort="250.0" lower="-3.14" upper="3.14" velocity="10.0"/>
    <axis xyz="0 0 1"/>
  </joint>
  <link name="tibia_link_4">
    <visual>
      <origin rpy="0.0 0.0 0.0" xyz="0.0 -0.15 0.0"/>
      <geometry>
        <box size="0.03 0.27 0.01"/>
      </geometry>
      <material name="black"/>
    </visual>
    <collision>
      <origin rpy="0.0 0.0 0.0" xyz="0.0 -0.15 0.0"/>
      <geometry>
        <box size="0.03 0.27 0.01"/>
      </geometry>
    </collision>
    <inertial>
      <origin rpy="0.0 0.0 0.0" xyz="0.0 -0.15 0.0"/>
      <mass value="0.401"/>
      <inertia ixx="0.002439416666666667" ixy="0.0" ixz="0.0" iyy="3.341666666666667e-05" iyz="0.0" izz="0.00246615"/>
    </inertial>
  </link>
  <gazebo reference="tibia_link_4">
    <material>Gazebo/Black</material>
  </gazebo>
  <!-- FOOT JOINT AND LINK -->
  <joint name="foot_joint_4" type="fixed">
    <origin rpy="0.0 0.0 0.0" xyz="0.0 -0.295 0.0"/>
    <parent link="tibia_link_4"/>
    <child link="foot_link_4"/>
  </joint>
  <link name="foot_link_4">
    <visual>
      <origin rpy="0.0 0.0 0.0" xyz="0.0 0.0 0.0"/>
      <geometry>
        <sphere radius="0.025"/>
      </geometry>
      <material name="white"/>
    </visual>
    <collision>
      <origin rpy="0.0 0.0 0.0" xyz="0.0 0.0 0.0"/>
      <geometry>
        <sphere radius="0.025"/>
      </geometry>
    </collision>
    <inertial>
      <origin rpy="0.0 0.0 0.0" xyz="0.0 0.0 0.0"/>
      <mass value="0.001"/>
      <inertia ixx="2.5000000000000004e-07" ixy="0.0" ixz="0.0" iyy="2.5000000000000004e-07" iyz="0.0" izz="2.5000000000000004e-07"/>
    </inertial>
  </link>
  <gazebo reference="foot_link_4">
    <material>Gazebo/White</material>
  </gazebo>
  <!-- COXA JOINT AND LINK-->
  <joint name="coxa_joint_5" type="revolute">
    <origin rpy="0.0 0.0 3.14" xyz="-0.275 0.2 -0.15"/>
    <parent link="body_link"/>
    <child link="coxa_link_5"/>
    <limit effort="250.0" lower="-3.14" upper="3.14" velocity="10.0"/>
    <axis xyz="0 0 1"/>
    <!--dynamics damping="10.0" friction="10.0"/-->
  </joint>
  <link name="coxa_link_5">
    <visual>
      <origin rpy="0.0 1.57 0.0" xyz="0.03 -0.05 -0.05"/>
      <geometry>
        <cylinder length="0.1" radius="0.05"/>
      </geometry>
      <material name="red"/>
    </visual>
    <collision>
      <origin rpy="0.0 1.57 0.0" xyz="0.03 -0.05 -0.05"/>
      <geometry>
        <cylinder length="0.1" radius="0.05"/>
      </geometry>
    </collision>
    <inertial>
      <origin rpy="0.0 1.57 0.0" xyz="0.03 -0.05 -0.05"/>
      <mass value="0.301"/>
      <inertia ixx="0.00043895833333333336" ixy="0.0" ixz="0.0" iyy="0.00043895833333333336" iyz="0.0" izz="0.00037625000000000007"/>
    </inertial>
  </link>
  <gazebo reference="coxa_link_5">
    <material>Gazebo/Blue</material>
  </gazebo>
  <!-- FEMUR JOINT AND LINK-->
  <joint name="femur_joint_5" type="revolute">
    <origin rpy="0.0 -1.57 0.0" xyz="0.07 -0.05 -0.05"/>
    <parent link="coxa_link_5"/>
    <child link="femur_link_5"/>
    <limit effort="250.0" lower="-3.14" upper="3.14" velocity="10.0"/>
    <axis xyz="0 0 1"/>
  </joint>
  <link name="femur_link_5">
    <visual>
      <origin rpy="0.0 0.0 0.0" xyz="0.0 -0.15 -0.03"/>
      <geometry>
        <box size="0.03 0.3 0.01"/>
      </geometry>
      <material name="orange"/>
    </visual>
    <collision>
      <origin rpy="0.0 0.0 0.0" xyz="0.0 -0.15 -0.03"/>
      <geometry>
        <box size="0.03 0.3 0.01"/>
      </geometry>
    </collision>
    <inertial>
      <origin rpy="0.0 0.0 0.0" xyz="0.0 -0.15 -0.03"/>
      <mass value="0.501"/>
      <inertia ixx="0.0037616749999999995" ixy="0.0" ixz="0.0" iyy="4.175e-05" iyz="0.0" izz="0.0037950749999999993"/>
    </inertial>
  </link>
  <gazebo reference="femur_link_5">
    <material>Gazebo/Orange</material>
  </gazebo>
  <!-- TIBIA JOINT AND LINK -->
  <joint name="tibia_joint_5" type="revolute">
    <origin rpy="0.0 3.14 0.0" xyz="0.0 -0.3 -0.01"/>
    <parent link="femur_link_5"/>
    <child link="tibia_link_5"/>
    <limit effort="250.0" lower="-3.14" upper="3.14" velocity="10.0"/>
    <axis xyz="0 0 1"/>
  </joint>
  <link name="tibia_link_5">
    <visual>
      <origin rpy="0.0 0.0 0.0" xyz="0.0 -0.15 0.0"/>
      <geometry>
        <box size="0.03 0.27 0.01"/>
      </geometry>
      <material name="black"/>
    </visual>
    <collision>
      <origin rpy="0.0 0.0 0.0" xyz="0.0 -0.15 0.0"/>
      <geometry>
        <box size="0.03 0.27 0.01"/>
      </geometry>
    </collision>
    <inertial>
      <origin rpy="0.0 0.0 0.0" xyz="0.0 -0.15 0.0"/>
      <mass value="0.401"/>
      <inertia ixx="0.002439416666666667" ixy="0.0" ixz="0.0" iyy="3.341666666666667e-05" iyz="0.0" izz="0.00246615"/>
    </inertial>
  </link>
  <gazebo reference="tibia_link_5">
    <material>Gazebo/Black</material>
  </gazebo>
  <!-- FOOT JOINT AND LINK -->
  <joint name="foot_joint_5" type="fixed">
    <origin rpy="0.0 0.0 0.0" xyz="0.0 -0.295 0.0"/>
    <parent link="tibia_link_5"/>
    <child link="foot_link_5"/>
  </joint>
  <link name="foot_link_5">
    <visual>
      <origin rpy="0.0 0.0 0.0" xyz="0.0 0.0 0.0"/>
      <geometry>
        <sphere radius="0.025"/>
      </geometry>
      <material name="white"/>
    </visual>
    <collision>
      <origin rpy="0.0 0.0 0.0" xyz="0.0 0.0 0.0"/>
      <geometry>
        <sphere radius="0.025"/>
      </geometry>
    </collision>
    <inertial>
      <origin rpy="0.0 0.0 0.0" xyz="0.0 0.0 0.0"/>
      <mass value="0.001"/>
      <inertia ixx="2.5000000000000004e-07" ixy="0.0" ixz="0.0" iyy="2.5000000000000004e-07" iyz="0.0" izz="2.5000000000000004e-07"/>
    </inertial>
  </link>
  <gazebo reference="foot_link_5">
    <material>Gazebo/White</material>
  </gazebo>
</robot>
